<?xml version="1.0"?>
<robot xmlns:xacro="http://www.ros.org/wiki/xacro">
    <xacro:include filename="inertial_macros.xacro"/>

    <material name="white">
        <color rgba="1 1 1 1" />
    </material>

    <material name="orange">
        <color rgba="1 0.3 0.1 1"/>
    </material>

    <material name="blue">
        <color rgba="0.2 0.2 1 1"/>
    </material>

    <material name="black">
        <color rgba="0 0 0 1"/>
    </material>

    <material name="red">
        <color rgba="1 0 0 1"/>
    </material>

    <material name="gray">
        <color rgba="0.6 0.6 0.6 1"/>
    </material>

    <material name="dark_gray">
        <color rgba="0.3 0.3 0.3 1"/>
    </material>

    <material name="light_gray">
        <color rgba="0.8 0.8 0.8 1"/>
    </material>

    <material name="yellow">
        <color rgba="1 1 0 1"/>
    </material>

    <material name="green">
        <color rgba="0 1 0 1"/>
    </material>

    <material name="cyan">
        <color rgba="0 1 1 1"/>
    </material>

    <material name="magenta">
        <color rgba="1 0 1 1"/>
    </material>

    <material name="transparent_red">
        <color rgba="1 0 0 0.4"/>
    </material>

    <material name="transparent_blue">
        <color rgba="0 0 1 0.4"/>
    </material>

    <material name="transparent_green">
        <color rgba="0 1 0 0.4"/>
    </material>

    <material name="transparent_gray">
        <color rgba="0.5 0.5 0.5 0.4"/>
    </material>

    <!-- base link-->

    <link name="base_link">
        
    </link>

    <!-- chassis link -->

    <joint name="chassis_joint" type="fixed">
        <parent link="base_link"/>
        <child link="chassis_link"/>
        <origin xyz="0 0 0" rpy="0 0 0"/>
    </joint>


    <link name="chassis_link">
        <visual>
            <origin xyz="0 0 0.1" rpy="0 0 0"/>   
            <geometry>
                <cylinder radius="0.5" length="0.2"/>
            </geometry>
            <material name="cyan"/>
        </visual>
        <collision>
            <origin xyz="0 0 0.1" rpy="0 0 0"/>   
            <geometry>
                <cylinder radius="0.5" length="0.2"/>
            </geometry>
            <material name="transparent_gray"/>
        </collision>
        <xacro:inertial_cylinder mass="5" length="0.2" radius="0.5">
            <origin xyz="0 0 0.1" rpy="0 0 0"/>
        </xacro:inertial_cylinder>
    </link>

    <!-- left wheel link-->
    <joint name="left_wheel_joint" type="continuous">
        <parent link="base_link"/>
        <child link="left_wheel_link"/>
        <origin xyz="0 0.5 0" rpy="-${pi/2} 0 0"/>
        <axis xyz="0 0 1"/>
    </joint>

    <link name="left_wheel_link">
        <visual>
            <geometry>
                <cylinder radius="0.1" length="0.05"/>
            </geometry>
            <material name="black"/>
        </visual>
        <collision>
            <geometry>
                <cylinder radius="0.1" length="0.05"/>
            </geometry>
            <material name="black"/>
        </collision>
        <xacro:inertial_cylinder mass="1" length="0.05" radius="0.1">
            <origin xyz="0 0 0" rpy="0 0 0"/>
        </xacro:inertial_cylinder>
    </link>
    
    <!-- right wheel link-->
    <joint name="right_wheel_joint" type="continuous">
        <parent link="base_link"/>
        <child link="right_wheel_link"/>
        <origin xyz="0 -0.5 0" rpy="${pi/2} 0 0"/>
        <axis xyz="0 0 -1"/>
    </joint>

    <link name="right_wheel_link">
        <visual>
            <geometry>
                <cylinder radius="0.1" length="0.05"/>
            </geometry>
            <material name="black"/>
        </visual>
        <collision>
            <geometry>
                <cylinder radius="0.1" length="0.05"/>
            </geometry>
            <material name="black"/>
        </collision>
        <xacro:inertial_cylinder mass="1" length="0.05" radius="0.1">
            <origin xyz="0 0 0" rpy="0 0 0"/>
        </xacro:inertial_cylinder>
    </link>

    <!--caster wheel limk-->
    <joint name="back_caster_wheel_joint" type="fixed">
        <parent link="base_link"/>
        <child link="back_caster_wheel_link"/>
        <origin xyz="-0.3 0 0" rpy="0 0 0"/>
    </joint>
    <link name="back_caster_wheel_link">
        <visual>
            <geometry>
                <sphere radius="0.1"/>
            </geometry>
            <material name="black"/>
        </visual>
        <collision>
            <geometry>
                <sphere radius="0.1"/>
            </geometry>
            <material name="black"/>
        </collision>
        <xacro:inertial_sphere mass="0.5" radius="0.1">
            <origin xyz="0 0 0" rpy="0 0 0"/>
        </xacro:inertial_sphere>
    </link>

    <joint name="front_caster_wheel_joint" type="fixed">
        <parent link="base_link"/>
        <child link="front_caster_wheel_link"/>
        <origin xyz="0.3 0 0" rpy="0 0 0"/>
    </joint>
    <link name="front_caster_wheel_link">
        <visual>
            <geometry>
                <sphere radius="0.1"/>
            </geometry>
            <material name="black"/>
        </visual>
        <collision>
            <geometry>
                <sphere radius="0.1"/>
            </geometry>
            <material name="black"/>
        </collision>
        <xacro:inertial_sphere mass="0.5" radius="0.1">
            <origin xyz="0 0 0" rpy="0 0 0"/>
        </xacro:inertial_sphere>
    </link>

</robot>